Workbook
Name in_tam_usd: Inputs!$B$13
Name in_sam_usd: Inputs!$B$14
Name in_som_usd: Inputs!$B$15
Name in_market_growth_pct: Inputs!$B$16
Name in_competitors_count: Inputs!$B$17
Name in_competitor_strength: Inputs!$B$18
Name in_score_problem_severity: Inputs!$B$20
Name in_score_problem_frequency: Inputs!$B$21
Name in_score_willingness_to_pay: Inputs!$B$22
Name in_score_market_timing: Inputs!$B$23
Name in_score_moat_tech: Inputs!$B$24
Name in_score_moat_data: Inputs!$B$25
Name in_score_moat_brand: Inputs!$B$26
Name in_score_team_domain: Inputs!$B$27
Name in_score_team_execution: Inputs!$B$28
Name in_score_team_completeness: Inputs!$B$29
Name in_score_gtm_clarity: Inputs!$B$30
Name in_score_unit_economics: Inputs!$B$31
Name in_score_capital_efficiency: Inputs!$B$32
Name in_score_regulatory_risk: Inputs!$B$33
Name in_score_ai_resilience: Inputs!$B$34
Name in_score_scalability: Inputs!$B$35
Name in_score_ip_strength: Inputs!$B$36
Name in_rev_y1: Inputs!$B$38
Name in_rev_growth_y2: Inputs!$B$39
Name in_rev_growth_y3: Inputs!$B$40
Name in_rev_growth_y4: Inputs!$B$41
Name in_rev_growth_y5: Inputs!$B$42
Name in_gross_margin: Inputs!$B$43
Name in_opex_pct_rev: Inputs!$B$44
Name in_tax_rate: Inputs!$B$45
Name in_capex_pct_rev: Inputs!$B$46
Name in_nwc_pct_rev: Inputs!$B$47
Name in_discount_rate: Inputs!$B$48
Name in_terminal_growth: Inputs!$B$49
Name in_net_debt_usd: Inputs!$B$50
Name in_comp_rev_multiple: Inputs!$B$52
Name in_comp_ebitda_multiple: Inputs!$B$53
Name in_comp_ntm_revenue: Inputs!$B$54
Name in_comp_ntm_ebitda: Inputs!$B$55
Name in_berkus_idea: Inputs!$B$57
Name in_berkus_prototype: Inputs!$B$58
Name in_berkus_team: Inputs!$B$59
Name in_berkus_relationships: Inputs!$B$60
Name in_berkus_sales: Inputs!$B$61
Name in_scorecard_avg_premoney: Inputs!$B$62
Name in_vc_exit_value: Inputs!$B$63
Name in_vc_target_roi: Inputs!$B$64
Name in_vc_years_to_exit: Inputs!$B$65
Name in_patent_count: Inputs!$B$67
Name in_patent_dev_cost_usd: Inputs!$B$68
Name in_patent_comparable_sale_usd: Inputs!$B$69
Name in_patent_royalty_rate: Inputs!$B$70
Name in_patent_revenue_attributable: Inputs!$B$71
Name in_patent_useful_life_years: Inputs!$B$72
Name in_target_headcount_y1: Inputs!$B$74
Name in_target_headcount_y3: Inputs!$B$75
Name in_avg_fully_loaded_cost: Inputs!$B$76
Name in_ai_automation_target: Inputs!$B$77
Name in_esop_pool_pct: Inputs!$B$79

Sheet Summary
A1: MeetingROI — Summary
A2: Calendar-integrated agent that prices every meeting in real $, scores decisions-per-hour, and auto-converts low-value recurrings to async.
A4: Composite score (1-5) | B4: =Scorecard!C16 -> 3.6404635
A5: Score (0-100) | B5: =Scorecard!C17 -> 66.011587
A6: Verdict | B6: =Scorecard!C18 -> GO
A8: DCF Equity Value (USD) | B8: =Valuation_DCF!B19 -> 2445239.9
A9: Comparables Midpoint (USD) | B9: =Valuation_Comps!B5 -> 6120000
A10: Berkus (USD) | B10: =Valuation_EarlyStage!B3 -> 1550000
A11: Scorecard (USD) | B11: =Valuation_EarlyStage!B4 -> 6067439.2
A12: VC method (USD) | B12: =Valuation_EarlyStage!B5 -> 16666667
A13: First Chicago weighted | B13: =Valuation_EarlyStage!B9 -> 4823810
A14: Patent midpoint (USD) | B14: =Valuation_Patent!B7 -> 0
A16: Org cost Y1 (USD) | B16: =Org!I23 -> 948000
A17: Org cost Y3 (USD) | B17: =Org!J23 -> 4236000

Sheet Inputs
A1: Idea Evaluator — Inputs
A2: Edit yellow cells. Other sheets recompute automatically.
A4: IDEA
A5: Idea / company name | B5: MeetingROI
A6: One-line description | B6: Calendar-integrated agent that prices every meeting in real $, scores decisions-per-hour, and auto-converts low-value recurrings to async.
A7: Problem being solved (2-4 sentences) | B7: Mid-market companies waste $250B+/yr in unproductive meetings. r/Entrepreneur thread on this hit 89K upvotes / 12K comments. People-managers can name the problem but lack quantified, per-meeting evidence to push back, and no system enforces hygiene at the calendar layer.
A8: Proposed solution | B8: OAuth into Google/Microsoft calendars + HRIS for salary bands. Compute a real $-cost per invite using attendee bands, score outcome density via meeting-doc + transcript analysis, and surface a weekly leaderboard + auto-suggest 'cancel/shrink/async' actions one-click-applied to the calendar.
A9: Primary target customer / ICP | B9: VP People / Chief of Staff at 500-5000 person tech-forward firms in NA/EU.
A10: Initial geography | B10: United States + EU
A11: Stage | B11: prototype
A12: MARKET
A13: TAM in USD (total addressable market) | B13: 8000000000
A14: SAM in USD (serviceable addressable) | B14: 1200000000
A15: SOM in USD (serviceable obtainable, yr-5) | B15: 60000000
A16: Market CAGR (e.g. 0.15 for 15%) | B16: 0.22
A17: Number of meaningful competitors | B17: 7
A18: Strongest competitor strength (1=weak,5=dominant) | B18: 3
A19: RUBRIC
A20: Problem severity / pain (1-5) | B20: 4 | C20: How acute is the pain? 5 = hair-on-fire.
A21: Problem frequency (1-5) | B21: 5
A22: Customer willingness to pay (1-5) | B22: 3
A23: Market timing / tailwinds (1-5) | B23: 4
A24: Technology moat / defensibility (1-5) | B24: 2
A25: Data moat / network effects (1-5) | B25: 4
A26: Brand / distribution moat (1-5) | B26: 2
A27: Team domain expertise (1-5) | B27: 3
A28: Team execution track record (1-5) | B28: 4
A29: Team completeness (1-5) | B29: 3
A30: GTM clarity & channel fit (1-5) | B30: 4
A31: Unit economics health (1-5) | B31: 4
A32: Capital efficiency (1-5) | B32: 4
A33: Regulatory safety (5=safe,1=heavy risk) | B33: 3
A34: AI-disruption resilience (5=AI helps you,1=AI kills you) | B34: 3 | C34: Will commodity LLMs eat your wedge in 24 months? Higher = safer/benefiting.
A35: Scalability of delivery (1-5) | B35: 5
A36: IP / patent strength (1-5) | B36: 1
A37: FINANCIALS
A38: Projected revenue Year 1 (USD) | B38: 240000
A39: Revenue growth Y2 | B39: 3
A40: Revenue growth Y3 | B40: 2
A41: Revenue growth Y4 | B41: 1.2
...

Sheet Scorecard
A1: Evaluation Scorecard
A3: Category | B3: Weight | C3: Avg Score (1-5) | D3: Sub-scores
A4: Problem | B4: 0.12 | C4: =AVERAGE(in_score_problem_severity,in_score_problem_frequency,in_score_willingness_to_pay) -> 4 | D4: problem_severity, problem_frequency, willingness_to_pay
A5: Market & Timing | B5: 0.12 | C5: =AVERAGE(in_score_market_timing) -> 4 | D5: market_timing
A6: Moat | B6: 0.14 | C6: =AVERAGE(in_score_moat_tech,in_score_moat_data,in_score_moat_brand,in_score_ip_strength) -> 2.25 | D6: moat_tech, moat_data, moat_brand, ip_strength
A7: Team | B7: 0.15 | C7: =AVERAGE(in_score_team_domain,in_score_team_execution,in_score_team_completeness) -> 3.3333333 | D7: team_domain, team_execution, team_completeness
A8: GTM | B8: 0.08 | C8: =AVERAGE(in_score_gtm_clarity) -> 4 | D8: gtm_clarity
A9: Unit Economics | B9: 0.1 | C9: =AVERAGE(in_score_unit_economics,in_score_capital_efficiency) -> 4 | D9: unit_economics, capital_efficiency
A10: Scalability | B10: 0.07 | C10: =AVERAGE(in_score_scalability) -> 5 | D10: scalability
A11: Regulatory | B11: 0.05 | C11: =AVERAGE(in_score_regulatory_risk) -> 3 | D11: regulatory_risk
A12: AI Resilience | B12: 0.17 | C12: =AVERAGE(in_score_ai_resilience) -> 3 | D12: ai_resilience
A14: Weighted avg (1-5) | C14: =SUMPRODUCT(B4:B12,C4:C12) -> 3.505
A15: Market-size bonus (TAM) | C15: =MAX(-1,MIN(1,LOG10(MAX(1,in_tam_usd)/1000000000)))*0.15 -> 0.1354635
A16: Composite (1-5) | C16: =MAX(1,MIN(5,C14+C15)) -> 3.6404635
A17: Score (0-100) | C17: =(C16-1)/4*100 -> 66.011587
A18: Verdict | C18: =IF(C17>=75,"STRONG GO",IF(C17>=60,"GO",IF(C17>=45,"CONDITIONAL",IF(C17>=30,"WEAK","NO-GO")))) -> GO

Sheet Org
A1: AI-Proof Org Structure
A3: Function | B3: Role | C3: Level | D3: HC Y1 | E3: HC Y3 | F3: Automation % | G3: Reports to | H3: AI augmentation | I3: Cost Y1 (USD) | J3: Cost Y3 (USD)
A4: Leadership | B4: CEO / Founder | C4: C | D4: =ROUND(1.0/13.2*in_target_headcount_y1,1) -> 0.6 | E4: =ROUND(1.0/30.0*in_target_headcount_y3,1) -> 1.2 | F4: =ROUND(0.2*0.7+in_ai_automation_target*0.3,2) -> 0.34 | G4: Board | H4: Strategy synthesis, investor narrative drafting, competitive intel via AI research agents. | I4: =D4*in_avg_fully_loaded_cost -> 72000 | J4: =E4*in_avg_fully_loaded_cost -> 144000
A5: Leadership | B5: CTO / Chief AI Architect | C5: C | D5: =ROUND(1.0/13.2*in_target_headcount_y1,1) -> 0.6 | E5: =ROUND(1.0/30.0*in_target_headcount_y3,1) -> 1.2 | F5: =ROUND(0.3*0.7+in_ai_automation_target*0.3,2) -> 0.41 | G5: CEO | H5: Architecture review with AI pair, code review automation, AI-assisted hiring loops. | I5: =D5*in_avg_fully_loaded_cost -> 72000 | J5: =E5*in_avg_fully_loaded_cost -> 144000
A6: Leadership | B6: Head of Autonomous Operations | C6: C | D6: =ROUND(0.0/13.2*in_target_headcount_y1,1) -> 0 | E6: =ROUND(1.0/30.0*in_target_headcount_y3,1) -> 1.2 | F6: =ROUND(0.4*0.7+in_ai_automation_target*0.3,2) -> 0.48 | G6: CEO | H6: AI-run dashboards, automated reporting, exception-only escalation; designs the human-in-the-loop seams. | I6: =D6*in_avg_fully_loaded_cost -> 0 | J6: =E6*in_avg_fully_loaded_cost -> 144000
A7: Product | B7: Head of Product (AI-Native) | C7: L | D7: =ROUND(0.5/13.2*in_target_headcount_y1,1) -> 0.3 | E7: =ROUND(1.0/30.0*in_target_headcount_y3,1) -> 1.2 | F7: =ROUND(0.3*0.7+in_ai_automation_target*0.3,2) -> 0.41 | G7: CEO | H7: AI user-research synthesis, PRD drafting copilots, AB-test analysis automation. | I7: =D7*in_avg_fully_loaded_cost -> 36000 | J7: =E7*in_avg_fully_loaded_cost -> 144000
A8: Product | B8: Product Engineer | C8: S | D8: =ROUND(1.0/13.2*in_target_headcount_y1,1) -> 0.6 | E8: =ROUND(2.0/30.0*in_target_headcount_y3,1) -> 2.3 | F8: =ROUND(0.4*0.7+in_ai_automation_target*0.3,2) -> 0.48 | G8: Head of Product | H8: Ships, not just specs: AI-assisted prototypes, transcript coding, competitive scans. | I8: =D8*in_avg_fully_loaded_cost -> 72000 | J8: =E8*in_avg_fully_loaded_cost -> 276000
A9: Product | B9: Product Designer (AI-Augmented) | C9: S | D9: =ROUND(1.0/13.2*in_target_headcount_y1,1) -> 0.6 | E9: =ROUND(2.0/30.0*in_target_headcount_y3,1) -> 2.3 | F9: =ROUND(0.5*0.7+in_ai_automation_target*0.3,2) -> 0.54 | G9: Head of Product | H9: Generative design exploration, copy variants, accessibility audits via AI. | I9: =D9*in_avg_fully_loaded_cost -> 72000 | J9: =E9*in_avg_fully_loaded_cost -> 276000
A10: Engineering | B10: Systems Architect | C10: L | D10: =ROUND(1.0/13.2*in_target_headcount_y1,1) -> 0.6 | E10: =ROUND(1.5/30.0*in_target_headcount_y3,1) -> 1.8 | F10: =ROUND(0.25*0.7+in_ai_automation_target*0.3,2) -> 0.37 | G10: CTO | H10: AI architecture critic, automated design-doc review, owns the eval+observability spine. | I10: =D10*in_avg_fully_loaded_cost -> 72000 | J10: =E10*in_avg_fully_loaded_cost -> 216000
A11: Engineering | B11: Forward-Deployed AI Engineer | C11: S | D11: =ROUND(2.0/13.2*in_target_headcount_y1,1) -> 1.2 | E11: =ROUND(4.0/30.0*in_target_headcount_y3,1) -> 4.7 | F11: =ROUND(0.55*0.7+in_ai_automation_target*0.3,2) -> 0.58 | G11: Systems Architect | H11: Claude/Copilot pair-programming, AI test-gen, AI code review on PRs, deploys with customers. | I11: =D11*in_avg_fully_loaded_cost -> 144000 | J11: =E11*in_avg_fully_loaded_cost -> 564000
A12: Engineering | B12: Applied AI Engineer | C12: S | D12: =ROUND(1.0/13.2*in_target_headcount_y1,1) -> 0.6 | E12: =ROUND(2.0/30.0*in_target_headcount_y3,1) -> 2.3 | F12: =ROUND(0.4*0.7+in_ai_automation_target*0.3,2) -> 0.48 | G12: Systems Architect | H12: Owns the model layer; eval harness, dataset curation, prompt + retrieval tuning. | I12: =D12*in_avg_fully_loaded_cost -> 72000 | J12: =E12*in_avg_fully_loaded_cost -> 276000
A13: Engineering | B13: Platform / AI-Ops Engineer | C13: S | D13: =ROUND(0.5/13.2*in_target_headcount_y1,1) -> 0.3 | E13: =ROUND(1.5/30.0*in_target_headcount_y3,1) -> 1.8 | F13: =ROUND(0.6*0.7+in_ai_automation_target*0.3,2) -> 0.62 | G13: Systems Architect | H13: IaC generation, runbook automation, AI-driven incident triage, agent infra. | I13: =D13*in_avg_fully_loaded_cost -> 36000 | J13: =E13*in_avg_fully_loaded_cost -> 216000
A14: Engineering | B14: Eval & Quality Engineer | C14: S | D14: =ROUND(0.0/13.2*in_target_headcount_y1,1) -> 0 | E14: =ROUND(1.0/30.0*in_target_headcount_y3,1) -> 1.2 | F14: =ROUND(0.7*0.7+in_ai_automation_target*0.3,2) -> 0.69 | G14: Systems Architect | H14: Owns LLM evals + property tests; humans curate edge cases that agents miss. | I14: =D14*in_avg_fully_loaded_cost -> 0 | J14: =E14*in_avg_fully_loaded_cost -> 144000
A15: Data | B15: Decision Intelligence Lead | C15: L | D15: =ROUND(0.0/13.2*in_target_headcount_y1,1) -> 0 | E15: =ROUND(1.0/30.0*in_target_headcount_y3,1) -> 1.2 | F15: =ROUND(0.5*0.7+in_ai_automation_target*0.3,2) -> 0.54 | G15: CTO | H15: Natural-language analytics, AI-built dashboards, anomaly detection, causal experimentation. | I15: =D15*in_avg_fully_loaded_cost -> 0 | J15: =E15*in_avg_fully_loaded_cost -> 144000
A16: GTM | B16: Head of Revenue (AI-Native) | C16: L | D16: =ROUND(0.5/13.2*in_target_headcount_y1,1) -> 0.3 | E16: =ROUND(1.0/30.0*in_target_headcount_y3,1) -> 1.2 | F16: =ROUND(0.3*0.7+in_ai_automation_target*0.3,2) -> 0.41 | G16: CEO | H16: AI account research, call-summary intelligence, pipeline forecasting. | I16: =D16*in_avg_fully_loaded_cost -> 36000 | J16: =E16*in_avg_fully_loaded_cost -> 144000
A17: GTM | B17: Forward-Deployed Account Lead | C17: S | D17: =ROUND(1.0/13.2*in_target_headcount_y1,1) -> 0.6 | E17: =ROUND(3.0/30.0*in_target_headcount_y3,1) -> 3.5 | F17: =ROUND(0.4*0.7+in_ai_automation_target*0.3,2) -> 0.48 | G17: Head of Revenue | H17: AI prospecting, personalized outbound at scale, configures the customer's agent stack on-site. | I17: =D17*in_avg_fully_loaded_cost -> 72000 | J17: =E17*in_avg_fully_loaded_cost -> 420000
A18: GTM | B18: Growth Engineer | C18: S | D18: =ROUND(1.0/13.2*in_target_headcount_y1,1) -> 0.6 | E18: =ROUND(2.0/30.0*in_target_headcount_y3,1) -> 2.3 | F18: =ROUND(0.6*0.7+in_ai_automation_target*0.3,2) -> 0.62 | G18: Head of Revenue | H18: AI content engine, SEO clusters, paid creative variants, lifecycle email automation. | I18: =D18*in_avg_fully_loaded_cost -> 72000 | J18: =E18*in_avg_fully_loaded_cost -> 276000
A19: GTM | B19: Customer Outcomes Engineer | C19: S | D19: =ROUND(1.0/13.2*in_target_headcount_y1,1) -> 0.6 | E19: =ROUND(2.5/30.0*in_target_headcount_y3,1) -> 2.9 | F19: =ROUND(0.55*0.7+in_ai_automation_target*0.3,2) -> 0.58 | G19: Head of Revenue | H19: AI-drafted QBRs, churn prediction, T1 deflection by AI agents, escalation on intent. | I19: =D19*in_avg_fully_loaded_cost -> 72000 | J19: =E19*in_avg_fully_loaded_cost -> 348000
A20: Ops | B20: Finance Engineer | C20: S | D20: =ROUND(0.0/13.2*in_target_headcount_y1,1) -> 0 | E20: =ROUND(1.0/30.0*in_target_headcount_y3,1) -> 1.2 | F20: =ROUND(0.65*0.7+in_ai_automation_target*0.3,2) -> 0.65 | G20: Head of Autonomous Ops | H20: AI-built models, automated month-end, expense classification, scenario engines. | I20: =D20*in_avg_fully_loaded_cost -> 0 | J20: =E20*in_avg_fully_loaded_cost -> 144000
A21: Ops | B21: Talent & Team-Design Lead | C21: S | D21: =ROUND(0.5/13.2*in_target_headcount_y1,1) -> 0.3 | E21: =ROUND(1.0/30.0*in_target_headcount_y3,1) -> 1.2 | F21: =ROUND(0.5*0.7+in_ai_automation_target*0.3,2) -> 0.54 | G21: Head of Autonomous Ops | H21: AI-screened pipelines, structured-interview kits, onboarding bots, org-shape continuous design. | I21: =D21*in_avg_fully_loaded_cost -> 36000 | J21: =E21*in_avg_fully_loaded_cost -> 144000
A22: Ops | B22: Counsel (Fractional, AI-Assisted) | C22: S | D22: =ROUND(0.2/13.2*in_target_headcount_y1,1) -> 0.1 | E22: =ROUND(0.5/30.0*in_target_headcount_y3,1) -> 0.6 | F22: =ROUND(0.55*0.7+in_ai_automation_target*0.3,2) -> 0.58 | G22: CEO | H22: Fractional; AI-drafted contracts and policy redlines, human review on novel terms. | I22: =D22*in_avg_fully_loaded_cost -> 12000 | J22: =E22*in_avg_fully_loaded_cost -> 72000
C23: TOTAL | D23: =SUM(D4:D22) -> 7.9 | E23: =SUM(E4:E22) -> 35.3 | I23: =SUM(I4:I22) -> 948000 | J23: =SUM(J4:J22) -> 4236000

Sheet Valuation_DCF
A1: DCF Valuation
A3: Item | B3: Y1 | C3: Y2 | D3: Y3 | E3: Y4 | F3: Y5
A4: Revenue | B4: =in_rev_y1 -> 240000 | C4: =B4*(1+in_rev_growth_y2) -> 960000 | D4: =C4*(1+in_rev_growth_y3) -> 2880000 | E4: =D4*(1+in_rev_growth_y4) -> 6336000 | F4: =E4*(1+in_rev_growth_y5) -> 10771200
A5: Gross profit | B5: =B4*in_gross_margin -> 187200 | C5: =C4*in_gross_margin -> 748800 | D5: =D4*in_gross_margin -> 2246400 | E5: =E4*in_gross_margin -> 4942080 | F5: =F4*in_gross_margin -> 8401536
A6: Opex | B6: =B4*in_opex_pct_rev -> 132000 | C6: =C4*in_opex_pct_rev -> 528000 | D6: =D4*in_opex_pct_rev -> 1584000 | E6: =E4*in_opex_pct_rev -> 3484800 | F6: =F4*in_opex_pct_rev -> 5924160
A7: EBIT | B7: =B5-B6 -> 55200 | C7: =C5-C6 -> 220800 | D7: =D5-D6 -> 662400 | E7: =E5-E6 -> 1457280 | F7: =F5-F6 -> 2477376
A8: NOPAT | B8: =B7*(1-in_tax_rate) -> 41400 | C8: =C7*(1-in_tax_rate) -> 165600 | D8: =D7*(1-in_tax_rate) -> 496800 | E8: =E7*(1-in_tax_rate) -> 1092960 | F8: =F7*(1-in_tax_rate) -> 1858032
A9: CapEx | B9: =B4*in_capex_pct_rev -> 4800 | C9: =C4*in_capex_pct_rev -> 19200 | D9: =D4*in_capex_pct_rev -> 57600 | E9: =E4*in_capex_pct_rev -> 126720 | F9: =F4*in_capex_pct_rev -> 215424
A10: NWC | B10: =B4*in_nwc_pct_rev -> 9600 | C10: =C4*in_nwc_pct_rev -> 38400 | D10: =D4*in_nwc_pct_rev -> 115200 | E10: =E4*in_nwc_pct_rev -> 253440 | F10: =F4*in_nwc_pct_rev -> 430848
A11: ΔNWC | B11: =B10 -> 9600 | C11: =C10-B10 -> 28800 | D11: =D10-C10 -> 76800 | E11: =E10-D10 -> 138240 | F11: =F10-E10 -> 177408
A12: FCF | B12: =B8-B9-B11 -> 27000 | C12: =C8-C9-C11 -> 117600 | D12: =D8-D9-D11 -> 362400 | E12: =E8-E9-E11 -> 828000 | F12: =F8-F9-F11 -> 1465200
A13: Discount factor | B13: =1/(1+in_discount_rate)^1 -> 0.76923077 | C13: =1/(1+in_discount_rate)^2 -> 0.59171598 | D13: =1/(1+in_discount_rate)^3 -> 0.45516614 | E13: =1/(1+in_discount_rate)^4 -> 0.3501278 | F13: =1/(1+in_discount_rate)^5 -> 0.26932907
A14: PV of FCF | B14: =B12*B13 -> 20769.231 | C14: =C12*C13 -> 69585.799 | D14: =D12*D13 -> 164952.21 | E14: =E12*E13 -> 289905.82 | F14: =F12*F13 -> 394620.96
A16: Terminal value | B16: =F12*(1+in_terminal_growth)/(in_discount_rate-in_terminal_growth) -> 5589466.7
A17: PV of TV | B17: =B16/(1+in_discount_rate)^5 -> 1505405.9
A18: Enterprise Value | B18: =SUM(B14:F14)+B17 -> 2445239.9
A19: Equity Value | B19: =B18-in_net_debt_usd -> 2445239.9

Sheet Valuation_Comps
A1: Comparables Valuation
A3: By revenue multiple | B3: =in_comp_rev_multiple*in_comp_ntm_revenue -> 9600000
A4: By EBITDA multiple | B4: =in_comp_ebitda_multiple*in_comp_ntm_ebitda -> 2640000
A5: Midpoint | B5: =AVERAGE(B3:B4) -> 6120000

Sheet Valuation_EarlyStage
A1: Early-Stage Valuations
A3: Berkus total | B3: =in_berkus_idea+in_berkus_prototype+in_berkus_team+in_berkus_relationships+in_berkus_sales -> 1550000
A4: Scorecard (Payne) pre-money | B4: =in_scorecard_avg_premoney*Scorecard!C16/3 -> 6067439.2
A5: VC method pre-money | B5: =in_vc_exit_value/in_vc_target_roi -> 16666667
A6: First Chicago — success scenario | B6: =MAX(Valuation_DCF!B19,Valuation_Comps!B5)*1.5 -> 9180000
A7: First Chicago — base scenario | B7: =AVERAGE(Valuation_DCF!B19,Valuation_Comps!B5) -> 4282619.9
A8: First Chicago — downside scenario | B8: =B3 -> 1550000
A9: First Chicago — weighted | B9: =0.25*B6+0.5*B7+0.25*B8 -> 4823810

Sheet Valuation_Patent
A1: Patent / IP Valuation
A3: Cost approach (R&D + filing) | B3: =in_patent_dev_cost_usd -> 0
A4: Market approach (comparable sale) | B4: =in_patent_comparable_sale_usd -> 0
A5: Relief-from-royalty (PV) | B5: =in_patent_royalty_rate*in_patent_revenue_attributable*(1-(1+in_discount_rate)^-in_patent_useful_life_years)/in_discount_rate -> 0
A6: Income approach (20% margin, PV) | B6: =0.20*in_patent_revenue_attributable*(1-(1+in_discount_rate)^-in_patent_useful_life_years)/in_discount_rate -> 0
A7: Midpoint of approaches | B7: =AVERAGE(B3:B6) -> 0

Sheet Equity
A1: Founder Equity Split (Slicing-Pie style)
A2: Units = time%·salary_forgone + capital + ip_score·100k + role_criticality·50k. Edit Inputs sheet — this recomputes.
A4: Founder | B4: Time % | C4: Salary forgone | D4: Capital | E4: IP score | F4: Role criticality | G4: Units | H4: Final equity %
A5: =Inputs!$B$80 -> Founder A | B5: =in_founder1_time_pct -> 1 | C5: =in_founder1_salary_forgone_usd -> 100000 | D5: =in_founder1_capital_usd -> 0 | E5: =in_founder1_ip_score -> 3 | F5: =in_founder1_role_criticality -> 4 | G5: =B5*C5+D5+E5*100000+F5*50000 -> 600000 | H5: =IF($G$9=0,0,G5/$G$9*(1-in_esop_pool_pct)) -> 0.425
A6: =Inputs!$B$86 -> Founder B | B6: =in_founder2_time_pct -> 1 | C6: =in_founder2_salary_forgone_usd -> 100000 | D6: =in_founder2_capital_usd -> 0 | E6: =in_founder2_ip_score -> 3 | F6: =in_founder2_role_criticality -> 4 | G6: =B6*C6+D6+E6*100000+F6*50000 -> 600000 | H6: =IF($G$9=0,0,G6/$G$9*(1-in_esop_pool_pct)) -> 0.425
A7: =Inputs!$B$92 -> Founder C | B7: =in_founder3_time_pct -> 0 | C7: =in_founder3_salary_forgone_usd -> 0 | D7: =in_founder3_capital_usd -> 0 | E7: =in_founder3_ip_score -> 0 | F7: =in_founder3_role_criticality -> 0 | G7: =B7*C7+D7+E7*100000+F7*50000 -> 0 | H7: =IF($G$9=0,0,G7/$G$9*(1-in_esop_pool_pct)) -> 0
A8: =Inputs!$B$98 -> Founder D | B8: =in_founder4_time_pct -> 0 | C8: =in_founder4_salary_forgone_usd -> 0 | D8: =in_founder4_capital_usd -> 0 | E8: =in_founder4_ip_score -> 0 | F8: =in_founder4_role_criticality -> 0 | G8: =B8*C8+D8+E8*100000+F8*50000 -> 0 | H8: =IF($G$9=0,0,G8/$G$9*(1-in_esop_pool_pct)) -> 0
A9: TOTAL | G9: =SUM(G5:G8) -> 1200000
A10: ESOP pool | H10: =in_esop_pool_pct -> 0.15
A11: Check (=100%) | H11: =SUM(H5:H8)+H10 -> 1

Sheet Screening
A1: Portfolio Screening (this idea)
A2: Edit yellow cells. Compare the four methods — divergence flags scoring sensitivity.
A4: Monetary impact ($/yr if successful) | B4: 60000000
A5: Adoption (0-1) | B5: 0.5
A6: Business critical (0-1) | B6: 0.8
A7: Ownership (0 ext, 1 internal) | B7: 1
A8: Risk PoS (0-1) | B8: 0.8
A9: Time of replacement (yrs) | B9: 3
A10: Time to commercialize (yrs) | B10: 2
A11: Cost to develop ($) | B11: 960000
A14: Modified RICE | B14: =(B4*B5*B6*B7*B8*B9)/(B10*B11) -> 30 | C14: Reach × Impact × Confidence / Effort (Samyama variant)
A15: WSJF | B15: =(MIN(100,B4*B5*B8/100000)+MAX(0,MIN(1,1/MAX(B9,0.5)))*100+B6*100)/B10 -> 106.66667 | C15: (BV + TimeCriticality + RiskReduction) / Duration [SAFe]
A16: CD3 ($/yr per yr) | B16: =(B4*B5*B8)/B10 -> 12000000 | C16: Cost of Delay / Duration [Reinertsen]
A17: EMV (USD) | B17: =B8*(B4*B5)*B9-B11 -> 71040000 | C17: PoS × (annual value × life) − cost

Sheet Definitions
A1: Definitions & Method Notes
A3: Term | B3: Definition | C3: How it's used in this tool
A4: Reach (RICE) | B4: How many customers a project will impact. | C4: Captured as Monetary impact × Adoption fraction.
A5: Impact (RICE) | B5: How much a project shifts a strategic goal. | C5: Captured as Business-critical × Ownership.
A6: Confidence (RICE) | B6: How sure we are in the estimates. | C6: Captured as Risk PoS × Time of replacement.
A7: Effort (RICE) | B7: Total time and money required. | C7: Captured as Time to commercialize × Cost to develop.
A8: Modified RICE | B8: Samyama variant: (Reach × Impact × Confidence) / Effort. | C8: Quick portfolio-level screen — higher is better.
A9: WSJF | B9: Weighted Shortest Job First (SAFe): (Business Value + Time Criticality + Risk Reduction) / Duration. | C9: Use when you care about delivery sequencing and time-to-market.
A10: CD3 | B10: Cost of Delay ÷ Duration (Reinertsen). | C10: Use when you can estimate $/year lost by delaying the project.
A11: EMV | B11: Expected Monetary Value: PoS × (annual value × life) − cost. | C11: Use when comparing projects in dollars rather than scores.
A12: TAM/SAM/SOM | B12: Total / Serviceable / Obtainable market. | C12: Drives the market-size bonus on the composite score.
A13: Moat | B13: Durable defensibility (tech, data, brand, IP). | C13: Four sub-scores feed the Moat category (14% weight).
A14: AI Resilience | B14: Will commodity LLMs help or eat this wedge in 24 months? | C14: Heaviest single weight (17%) in the rubric — by design.
... A26: Income approach (IP) | B26: PV of incremental income enabled by the patent. | C26: Uses 20% margin proxy unless overridden.
A29: Rubric ↔ Screening cross-map
A30: Rubric category | B30: RICE/WSJF mapping | C30: Cross-check
A31: Problem | B31: Reach (severity × frequency × WTP) | C31: Low problem score + high RICE Reach => suspect inflated adoption.
A32: Market & Timing | B32: WSJF Time Criticality | C32: Strong timing => higher WSJF urgency, shorter Time of Replacement.
A33: Moat | B33: Time of Replacement (years) | C33: Weak moat (<3 yrs) caps WSJF and CD3 even if value is high.
A34: Team | B34: Confidence / Risk PoS | C34: Team gaps reduce risk_pos in EMV and Confidence in RICE.
A35: Unit Economics | B35: Cost of Delay numerator | C35: Drives the $-of-delay term in CD3.
A36: AI Resilience | B36: Time of Replacement (AI-driven) | C36: If AI eats this in 24 months, set time_of_replacement ≤ 2.
A37: Regulatory | B37: Risk PoS | C37: Heavy regulation reduces PoS; multiplies through EMV and WSJF.
